<?xml version="1.0" encoding="utf-8"?>
<!-- This URDF was automatically created by SolidWorks to URDF Exporter! Originally created by Stephen Brawner (brawner@gmail.com) 
     Commit Version: 1.6.0-4-g7f85cfe  Build Version: 1.6.7995.38578
     For more information, please see http://wiki.ros.org/sw_urdf_exporter -->
<robot
  name="zrobot">
  <link
    name="base_link">
    <inertial>
      <origin
        xyz="-0.053122 -0.000376 0.016153"
        rpy="0 0 0" />
      <mass
        value="3.826" />
      <inertia
        ixx="0.041164"
        ixy="-7.2E-05"
        ixz="0.001859"
        iyy="0.012512"
        iyz="-1.2E-05"
        izz="0.048942" />
    </inertial>
    <visual>
      <origin
        xyz="0 0 0"
        rpy="0 0 0" />
      <geometry>
        <mesh
          filename="../meshes/base_link.STL" />
      </geometry>
      <material
        name="">
        <color
          rgba="1 1 1 1" />
      </material>
    </visual>
    <!-- <collision>
      <origin
        xyz="0 0 0"
        rpy="0 0 0" />
      <geometry>
        <mesh
          filename="../meshes/base_link.STL" />
      </geometry>
    </collision> -->
    <collision>
      <origin
        xyz="-0.02 0 0.22"
        rpy="0 0 0" />
      <geometry>
        <box
          size="0.195 0.36 0.557" />
      </geometry>
    </collision>
  </link>
  <link
    name="L_hip_roll_link">
    <inertial>
      <origin
        xyz="0.0623 -4.8E-05 0.000293"
        rpy="0 0 0" />
      <mass
        value="1.0503" />
      <inertia
        ixx="0.001102"
        ixy="-1E-06"
        ixz="3E-06"
        iyy="0.001173"
        iyz="-1E-06"
        izz="0.001594" />
    </inertial>
    <visual>
      <origin
        xyz="0 0 0"
        rpy="0 0 0" />
      <geometry>
        <mesh
          filename="../meshes/L_hip_roll_link.STL" />
      </geometry>
      <material
        name="">
        <color
          rgba="1 1 1 1" />
      </material>
    </visual>
    <!-- <collision>
      <origin
        xyz="0 0 0"
        rpy="0 0 0" />
      <geometry>
        <mesh
          filename="../meshes/L_hip_roll_link.STL" />
      </geometry>
    </collision> -->
  </link>
  <joint
    name="L_hip_roll_joint"
    type="revolute">
    <origin
      xyz="-0.0715000000000026 0.135 0.00620000000000087"
      rpy="0 0 0" />
    <parent
      link="base_link" />
    <child
      link="L_hip_roll_link" />
    <axis
      xyz="1 0 0" />
    <limit
      lower="-0.4"
      upper="1.5"
      effort="1000"
      velocity="1000" />
  </joint>
  <link
    name="L_hip_yaw_link">
    <inertial>
      <origin
        xyz="0.000862 -0.001216 -0.064584"
        rpy="0 0 0" />
      <mass
        value="1.584" />
      <inertia
        ixx="0.002256"
        ixy="-1E-06"
        ixz="-1.9E-05"
        iyy="0.003465"
        iyz="8E-06"
        izz="0.002117" />
    </inertial>
    <visual>
      <origin
        xyz="0 0 0"
        rpy="0 0 0" />
      <geometry>
        <mesh
          filename="../meshes/L_hip_yaw_link.STL" />
      </geometry>
      <material
        name="">
        <color
          rgba="1 1 1 1" />
      </material>
    </visual>
    <!-- <collision>
      <origin
        xyz="0 0 0"
        rpy="0 0 0" />
      <geometry>
        <mesh
          filename="../meshes/L_hip_yaw_link.STL" />
      </geometry>
    </collision> -->
  </link>
  <joint
    name="L_hip_yaw_joint"
    type="revolute">
    <origin
      xyz="0.0650000000000002 0 -0.0219999999999869"
      rpy="0 0 0" />
    <parent
      link="L_hip_roll_link" />
    <child
      link="L_hip_yaw_link" />
    <axis
      xyz="0 0 1" />
    <limit
      lower="-1.0"
      upper="1.0"
      effort="1000"
      velocity="1000" />
  </joint>
  <link
    name="L_hip_pitch_link">
    <inertial>
      <origin
        xyz="0.000869 -0.013032 -0.26185"
        rpy="0 0 0" />
      <mass
        value="2.0026" />
      <inertia
        ixx="0.014864"
        ixy="2E-06"
        ixz="-5.3E-05"
        iyy="0.016027"
        iyz="0.000684"
        izz="0.002431" />
    </inertial>
    <visual>
      <origin
        xyz="0 0 0"
        rpy="0 0 0" />
      <geometry>
        <mesh
          filename="../meshes/L_hip_pitch_link.STL" />
      </geometry>
      <material
        name="">
        <color
          rgba="1 1 1 1" />
      </material>
    </visual>
    <!-- <collision>
      <origin
        xyz="0 0 0"
        rpy="0 0 0" />
      <geometry>
        <mesh
          filename="../meshes/L_hip_pitch_link.STL" />
      </geometry>
    </collision> -->
  </link>
  <joint
    name="L_hip_pitch_joint"
    type="revolute">
    <origin
      xyz="-3.49322273089925E-05 0.0204999702375277 -0.0670000000000057"
      rpy="0 0 0" />
    <parent
      link="L_hip_yaw_link" />
    <child
      link="L_hip_pitch_link" />
    <axis
      xyz="-0.00170401108835407 0.999998548172051 0" />
    <limit
      lower="-1.8"
      upper="1.3"
      effort="1000"
      velocity="1000" />
  </joint>
  <link
    name="L_knee_link">
    <inertial>
      <origin
        xyz="0.001783 -0.022897 -0.16039"
        rpy="0 0 0" />
      <mass
        value="1.4819" />
      <inertia
        ixx="0.009583"
        ixy="-1.1E-05"
        ixz="3E-05"
        iyy="0.008986"
        iyz="0.00051"
        izz="0.001248" />
    </inertial>
    <visual>
      <origin
        xyz="0 0 0"
        rpy="0 0 0" />
      <geometry>
        <mesh
          filename="../meshes/L_knee_link.STL" />
      </geometry>
      <material
        name="">
        <color
          rgba="1 1 1 1" />
      </material>
    </visual>
    <!-- <collision>
      <origin
        xyz="0 0 0"
        rpy="0 0 0" />
      <geometry>
        <mesh
          filename="../meshes/L_knee_link.STL" />
      </geometry>
    </collision> -->
  </link>
  <joint
    name="L_knee_joint"
    type="revolute">
    <origin
      xyz="0.000313115318114399 0.00500054081190004 -0.299999827583929"
      rpy="0 0 0" />
    <parent
      link="L_hip_pitch_link" />
    <child
      link="L_knee_link" />
    <axis
      xyz="0.0017040110883775 -0.999998548172051 0" />
    <limit
      lower="-1.9"
      upper="0"
      effort="1000"
      velocity="1000" />
  </joint>
  <link
    name="L_foot_pitch_link">
    <inertial>
      <origin
        xyz="4.2612E-05 -0.025 -1.9761E-11"
        rpy="0 0 0" />
      <mass
        value="0.027426" />
      <inertia
        ixx="3.5409E-06"
        ixy="6.6562E-15"
        ixz="5.1684E-09"
        iyy="3.5408E-06"
        iyz="3.9167E-12"
        izz="6.5768E-06" />
    </inertial>
    <visual>
      <origin
        xyz="0 0 0"
        rpy="0 0 0" />
      <geometry>
        <mesh
          filename="../meshes/L_foot_pitch_link.STL" />
      </geometry>
      <material
        name="">
        <color
          rgba="0.89804 0.91765 0.92941 1" />
      </material>
    </visual>
    <!-- <collision>
      <origin
        xyz="0 0 0"
        rpy="0 0 0" />
      <geometry>
        <mesh
          filename="../meshes/L_foot_pitch_link.STL" />
      </geometry>
    </collision> -->
  </link>
  <joint
    name="L_foot_pitch_joint"
    type="revolute">
    <origin
      xyz="0 -0.000500000153495384 -0.34999999999962"
      rpy="0 0 0" />
    <parent
      link="L_knee_link" />
    <child
      link="L_foot_pitch_link" />
    <axis
      xyz="0.00170401108836505 -0.999998548172051 0" />
    <limit
      lower="-0.4"
      upper="0.55"
      effort="1000"
      velocity="1000" />
  </joint>
  <link
    name="L_foot_roll_link">
    <inertial>
      <origin
        xyz="0.051071 8.7311E-05 -0.041358"
        rpy="0 0 0" />
      <mass
        value="0.66962" />
      <inertia
        ixx="0.00037577"
        ixy="3E-06"
        ixz="-1.7E-05"
        iyy="0.0019054"
        iyz="2.32E-08"
        izz="0.0020007" />
    </inertial>
    <visual>
      <origin
        xyz="0 0 0"
        rpy="0 0 0" />
      <geometry>
        <mesh
          filename="../meshes/L_foot_roll_link.STL" />
      </geometry>
      <material
        name="">
        <color
          rgba="0.89804 0.91765 0.92941 1" />
      </material>
    </visual>
    <collision>
      <origin
        xyz="0 0 0"
        rpy="0 0 0" />
      <geometry>
        <mesh
          filename="../meshes/L_foot_roll_link.STL" />
      </geometry>
    </collision>
  </link>
  <joint
    name="L_foot_roll_joint"
    type="revolute">
    <origin
      xyz="-0.0249573271314456 -0.0250425639196625 4.26002772095924E-05"
      rpy="0 0 0" />
    <parent
      link="L_foot_pitch_link" />
    <child
      link="L_foot_roll_link" />
    <axis
      xyz="0.999997096346211 0.00170400861446901 -0.0017040110883815" />
    <limit
      lower="-0.8"
      upper="0.8"
      effort="1000"
      velocity="1000" />
  </joint>
  <link
    name="R_hip_roll_link">
    <inertial>
      <origin
        xyz="0.0623 -4.8E-05 0.000293"
        rpy="0 0 0" />
      <mass
        value="1.0503" />
      <inertia
        ixx="0.001102"
        ixy="-1E-06"
        ixz="3E-06"
        iyy="0.001173"
        iyz="-1E-06"
        izz="0.001594" />
    </inertial>
    <visual>
      <origin
        xyz="0 0 0"
        rpy="0 0 0" />
      <geometry>
        <mesh
          filename="../meshes/R_hip_roll_link.STL" />
      </geometry>
      <material
        name="">
        <color
          rgba="1 1 1 1" />
      </material>
    </visual>
    <!-- <collision>
      <origin
        xyz="0 0 0"
        rpy="0 0 0" />
      <geometry>
        <mesh
          filename="../meshes/R_hip_roll_link.STL" />
      </geometry>
    </collision> -->
  </link>
  <joint
    name="R_hip_roll_joint"
    type="revolute">
    <origin
      xyz="-0.0715000000000037 -0.134999999999997 0.00619999999999687"
      rpy="0 0 0" />
    <parent
      link="base_link" />
    <child
      link="R_hip_roll_link" />
    <axis
      xyz="1 0 0" />
    <limit
      lower="-1.5"
      upper="0.4"
      effort="1000"
      velocity="1000" />
  </joint>
  <link
    name="R_hip_yaw_link">
    <inertial>
      <origin
        xyz="-0.000862 0.001216 -0.064584"
        rpy="0 0 0" />
      <mass
        value="1.584" />
      <inertia
        ixx="0.002256"
        ixy="-1E-06"
        ixz="1.9E-05"
        iyy="0.003465"
        iyz="-8E-06"
        izz="0.002117" />
    </inertial>
    <visual>
      <origin
        xyz="0 0 0"
        rpy="0 0 0" />
      <geometry>
        <mesh
          filename="../meshes/R_hip_yaw_link.STL" />
      </geometry>
      <material
        name="">
        <color
          rgba="1 1 1 1" />
      </material>
    </visual>
    <!-- <collision>
      <origin
        xyz="0 0 0"
        rpy="0 0 0" />
      <geometry>
        <mesh
          filename="../meshes/R_hip_yaw_link.STL" />
      </geometry>
    </collision> -->
  </link>
  <joint
    name="R_hip_yaw_joint"
    type="revolute">
    <origin
      xyz="0.0650000000000006 0 -0.0219999999999896"
      rpy="0 0 0" />
    <parent
      link="R_hip_roll_link" />
    <child
      link="R_hip_yaw_link" />
    <axis
      xyz="0 0 1" />
    <limit
      lower="-1.0"
      upper="1.0"
      effort="1000"
      velocity="1000" />
  </joint>
  <link
    name="R_hip_pitch_link">
    <inertial>
      <origin
        xyz="-0.000869 0.013032 -0.26185"
        rpy="0 0 0" />
      <mass
        value="2.0026" />
      <inertia
        ixx="0.014864"
        ixy="2E-06"
        ixz="5.3E-05"
        iyy="0.016027"
        iyz="-0.000684"
        izz="0.002431" />
    </inertial>
    <visual>
      <origin
        xyz="0 0 0"
        rpy="0 0 0" />
      <geometry>
        <mesh
          filename="../meshes/R_hip_pitch_link.STL" />
      </geometry>
      <material
        name="">
        <color
          rgba="1 1 1 1" />
      </material>
    </visual>
    <!-- <collision>
      <origin
        xyz="0 0 0"
        rpy="0 0 0" />
      <geometry>
        <mesh
          filename="../meshes/R_hip_pitch_link.STL" />
      </geometry>
    </collision> -->
  </link>
  <joint
    name="R_hip_pitch_joint"
    type="revolute">
    <origin
      xyz="3.49322273081043E-05 -0.0204999702375275 -0.0670000000000071"
      rpy="0 0 0" />
    <parent
      link="R_hip_yaw_link" />
    <child
      link="R_hip_pitch_link" />
    <axis
      xyz="0.0017040110883879 -0.999998548172051 0" />
    <limit
      lower="-1.3"
      upper="1.8"
      effort="1000"
      velocity="1000" />
  </joint>
  <link
    name="R_knee_link">
    <inertial>
      <origin
        xyz="-0.001997 0.023105 -0.16074"
        rpy="0 0 0" />
      <mass
        value="1.4819" />
      <inertia
        ixx="0.009567"
        ixy="-6E-06"
        ixz="0.000227"
        iyy="0.008973"
        iyz="-0.000507"
        izz="0.001256" />
    </inertial>
    <visual>
      <origin
        xyz="0 0 0"
        rpy="0 0 0" />
      <geometry>
        <mesh
          filename="../meshes/R_knee_link.STL" />
      </geometry>
      <material
        name="">
        <color
          rgba="1 1 1 1" />
      </material>
    </visual>
    <!-- <collision>
      <origin
        xyz="0 0 0"
        rpy="0 0 0" />
      <geometry>
        <mesh
          filename="../meshes/R_knee_link.STL" />
      </geometry>
    </collision> -->
  </link>
  <joint
    name="R_knee_joint"
    type="revolute">
    <origin
      xyz="-0.000313115318115953 -0.00500054081189905 -0.299999827583928"
      rpy="0 0 0" />
    <parent
      link="R_hip_pitch_link" />
    <child
      link="R_knee_link" />
    <axis
      xyz="-0.00170401108838362 0.999998548172051 0" />
    <limit
      lower="0"
      upper="1.9"
      effort="1000"
      velocity="1000" />
  </joint>
  <link
    name="R_foot_pitch_link">
    <inertial>
      <origin
        xyz="-4.2589E-05 0.025 -1.9761E-11"
        rpy="0 0 0" />
      <mass
        value="0.027426" />
      <inertia
        ixx="3.5409E-06"
        ixy="6.6562E-15"
        ixz="5.1684E-09"
        iyy="3.5408E-06"
        iyz="3.9167E-12"
        izz="6.5768E-06" />
    </inertial>
    <visual>
      <origin
        xyz="0 0 0"
        rpy="0 0 0" />
      <geometry>
        <mesh
          filename="../meshes/R_foot_pitch_link.STL" />
      </geometry>
      <material
        name="">
        <color
          rgba="0.89804 0.91765 0.92941 1" />
      </material>
    </visual>
    <!-- <collision>
      <origin
        xyz="0 0 0"
        rpy="0 0 0" />
      <geometry>
        <mesh
          filename="../meshes/R_foot_pitch_link.STL" />
      </geometry>
    </collision> -->
  </link>
  <joint
    name="R_foot_pitch_joint"
    type="revolute">
    <origin
      xyz="-0.00806100070657201 0.00048626467137769 -0.349907178855019"
      rpy="0 0 0" />
    <parent
      link="R_knee_link" />
    <child
      link="R_foot_pitch_link" />
    <axis
      xyz="-0.00170401108838948 0.999998548172051 0" />
    <limit
      lower="-0.55"
      upper="0.4"
      effort="1000"
      velocity="1000" />
  </joint>
  <link
    name="R_foot_roll_link">
    <inertial>
      <origin
        xyz="0.051071 8.7311E-05 -0.041358"
        rpy="0 0 0" />
      <mass
        value="0.66962" />
      <inertia
        ixx="0.00037577"
        ixy="3E-06"
        ixz="-1.7E-05"
        iyy="0.0019054"
        iyz="2.32E-08"
        izz="0.0020007" />
    </inertial>
    <visual>
      <origin
        xyz="0 0 0"
        rpy="0 0 0" />
      <geometry>
        <mesh
          filename="../meshes/R_foot_roll_link.STL" />
      </geometry>
      <material
        name="">
        <color
          rgba="0.89804 0.91765 0.92941 1" />
      </material>
    </visual>
    <collision>
      <origin
        xyz="0 0 0"
        rpy="0 0 0" />
      <geometry>
        <mesh
          filename="../meshes/R_foot_roll_link.STL" />
      </geometry>
    </collision>
  </link>
  <joint
    name="R_foot_roll_joint"
    type="revolute">
    <origin
      xyz="-0.0250425276858648 0.02495736348894 4.26002772095924E-05"
      rpy="0 0 0" />
    <parent
      link="R_foot_pitch_link" />
    <child
      link="R_foot_roll_link" />
    <axis
      xyz="0.999997096346211 0.00170400861445591 -0.0017040110883815" />
    <limit
      lower="-0.8"
      upper="0.8"
      effort="1000"
      velocity="1000" />
  </joint>
  <link
    name="chest_head_link">
    <inertial>
      <origin
        xyz="0.003148 0.000299 0.2816"
        rpy="0 0 0" />
      <mass
        value="8.5057" />
      <inertia
        ixx="0.15508"
        ixy="2.5E-05"
        ixz="0.003149"
        iyy="0.11141"
        iyz="0.000355"
        izz="0.060787" />
    </inertial>
    <visual>
      <origin
        xyz="0 0 0"
        rpy="0 0 0" />
      <geometry>
        <mesh
          filename="../meshes/chest_head_link.STL" />
      </geometry>
      <material
        name="">
        <color
          rgba="1 1 1 1" />
      </material>
    </visual>
    <!-- <collision>
      <origin
        xyz="0 0 0"
        rpy="0 0 0" />
      <geometry>
        <mesh
          filename="../meshes/chest_head_link.STL" />
      </geometry>
    </collision> -->
  </link>
  <joint
    name="chest_head_joint"
    type="fixed">
    <origin
      xyz="0 0 0.0527000000000102"
      rpy="0 0 0" />
    <parent
      link="base_link" />
    <child
      link="chest_head_link" />
    <axis
      xyz="0 0 1" />
  </joint>
  <link
    name="L_shoulder_pitch_link">
    <inertial>
      <origin
        xyz="-0.000499 0.063856 -0.002446"
        rpy="0 0 0" />
      <mass
        value="1.0024" />
      <inertia
        ixx="0.001494"
        ixy="-4E-06"
        ixz="4E-06"
        iyy="0.00099"
        iyz="2.2E-05"
        izz="0.001134" />
    </inertial>
    <visual>
      <origin
        xyz="0 0 0"
        rpy="0 0 0" />
      <geometry>
        <mesh
          filename="../meshes/L_shoulder_pitch_link.STL" />
      </geometry>
      <material
        name="">
        <color
          rgba="1 1 1 1" />
      </material>
    </visual>
    <!-- <collision>
      <origin
        xyz="0 0 0"
        rpy="0 0 0" />
      <geometry>
        <mesh
          filename="../meshes/L_shoulder_pitch_link.STL" />
      </geometry>
    </collision> -->
  </link>
  <joint
    name="L_shoulder_pitch_joint"
    type="fixed">
    <origin
      xyz="0 0.127499999999997 0.330000000000002"
      rpy="0 0 0" />
    <parent
      link="chest_head_link" />
    <child
      link="L_shoulder_pitch_link" />
    <axis
      xyz="0 1 0" />
  </joint>
  <link
    name="L_shoulder_roll_link">
    <inertial>
      <origin
        xyz="-0.017808 0.001558 -0.076904"
        rpy="0 0 0" />
      <mass
        value="0.46926" />
      <inertia
        ixx="0.000473"
        ixy="-1E-06"
        ixz="5.9E-05"
        iyy="0.000498"
        iyz="-1E-06"
        izz="0.000427" />
    </inertial>
    <visual>
      <origin
        xyz="0 0 0"
        rpy="0 0 0" />
      <geometry>
        <mesh
          filename="../meshes/L_shoulder_roll_link.STL" />
      </geometry>
      <material
        name="">
        <color
          rgba="1 1 1 1" />
      </material>
    </visual>
    <!-- <collision>
      <origin
        xyz="0 0 0"
        rpy="0 0 0" />
      <geometry>
        <mesh
          filename="../meshes/L_shoulder_roll_link.STL" />
      </geometry>
    </collision> -->
  </link>
  <joint
    name="L_shoulder_roll_joint"
    type="fixed">
    <origin
      xyz="0.0209980227067856 0.0689999999999997 -0.00211967978838579"
      rpy="0 0 0" />
    <parent
      link="L_shoulder_pitch_link" />
    <child
      link="L_shoulder_roll_link" />
    <axis
      xyz="-0.999999560849825 0 0.000937176695177002" />
  </joint>
  <link
    name="L_arm_yaw_link">
    <inertial>
      <origin
        xyz="-0.00112 -0.001525 -0.1198"
        rpy="0 0 0" />
      <mass
        value="0.49726" />
      <inertia
        ixx="0.000772"
        ixy="-6E-06"
        ixz="1E-05"
        iyy="0.000899"
        iyz="1.7E-05"
        izz="0.000312" />
    </inertial>
    <visual>
      <origin
        xyz="0 0 0"
        rpy="0 0 0" />
      <geometry>
        <mesh
          filename="../meshes/L_arm_yaw_link.STL" />
      </geometry>
      <material
        name="">
        <color
          rgba="1 1 1 1" />
      </material>
    </visual>
    <!-- <collision>
      <origin
        xyz="0 0 0"
        rpy="0 0 0" />
      <geometry>
        <mesh
          filename="../meshes/L_arm_yaw_link.STL" />
      </geometry>
    </collision> -->
  </link>
  <joint
    name="L_arm_yaw_joint"
    type="fixed">
    <origin
      xyz="-0.0211021299960445 0.00174168132372676 -0.108966355614004"
      rpy="0 0 0" />
    <parent
      link="L_shoulder_roll_link" />
    <child
      link="L_arm_yaw_link" />
    <axis
      xyz="-0.000937057047695522 0.0159787277406135 -0.999871892886224" />
  </joint>
  <link
    name="L_elbow_pitch_link">
    <inertial>
      <origin
        xyz="0.069668 -0.012372 -0.00026295"
        rpy="0 0 0" />
      <mass
        value="0.11269" />
      <inertia
        ixx="2.9039E-05"
        ixy="-2.9E-05"
        ixz="-1E-06"
        iyy="0.00025916"
        iyz="4.8439E-08"
        izz="0.00025445" />
    </inertial>
    <visual>
      <origin
        xyz="0 0 0"
        rpy="0 0 0" />
      <geometry>
        <mesh
          filename="../meshes/L_elbow_pitch_link.STL" />
      </geometry>
      <material
        name="">
        <color
          rgba="0.89804 0.91765 0.92941 1" />
      </material>
    </visual>
    <!-- <collision>
      <origin
        xyz="0 0 0"
        rpy="0 0 0" />
      <geometry>
        <mesh
          filename="../meshes/L_elbow_pitch_link.STL" />
      </geometry>
    </collision> -->
  </link>
  <joint
    name="L_elbow_pitch_joint"
    type="fixed">
    <origin
      xyz="0.000566901553395782 0.02062583537445 -0.133688083005685"
      rpy="0 0 0" />
    <parent
      link="L_arm_yaw_link" />
    <child
      link="L_elbow_pitch_link" />
    <axis
      xyz="-0.0374306593390553 -0.999172208497632 -0.0159324670848291" />
  </joint>
  <link
    name="R_shoulder_pitch_link">
    <inertial>
      <origin
        xyz="-0.000499 -0.063856 0.002446"
        rpy="0 0 0" />
      <mass
        value="1.0024" />
      <inertia
        ixx="0.001494"
        ixy="4E-06"
        ixz="-4E-06"
        iyy="0.00099"
        iyz="2.2E-05"
        izz="0.001134" />
    </inertial>
    <visual>
      <origin
        xyz="0 0 0"
        rpy="0 0 0" />
      <geometry>
        <mesh
          filename="../meshes/R_shoulder_pitch_link.STL" />
      </geometry>
      <material
        name="">
        <color
          rgba="1 1 1 1" />
      </material>
    </visual>
    <!-- <collision>
      <origin
        xyz="0 0 0"
        rpy="0 0 0" />
      <geometry>
        <mesh
          filename="../meshes/R_shoulder_pitch_link.STL" />
      </geometry>
    </collision> -->
  </link>
  <joint
    name="R_shoulder_pitch_joint"
    type="fixed">
    <origin
      xyz="0 -0.127500000000003 0.330000000000001"
      rpy="0 0 0" />
    <parent
      link="chest_head_link" />
    <child
      link="R_shoulder_pitch_link" />
    <axis
      xyz="0 -1 0" />
  </joint>
  <link
    name="R_shoulder_roll_link">
    <inertial>
      <origin
        xyz="-0.017664 0.001558 -0.076937"
        rpy="0 0 0" />
      <mass
        value="0.46926" />
      <inertia
        ixx="0.000474"
        ixy="-1E-06"
        ixz="5.9E-05"
        iyy="0.000498"
        iyz="-1E-06"
        izz="0.000427" />
    </inertial>
    <visual>
      <origin
        xyz="0 0 0"
        rpy="0 0 0" />
      <geometry>
        <mesh
          filename="../meshes/R_shoulder_roll_link.STL" />
      </geometry>
      <material
        name="">
        <color
          rgba="1 1 1 1" />
      </material>
    </visual>
    <!-- <collision>
      <origin
        xyz="0 0 0"
        rpy="0 0 0" />
      <geometry>
        <mesh
          filename="../meshes/R_shoulder_roll_link.STL" />
      </geometry>
    </collision> -->
  </link>
  <joint
    name="R_shoulder_roll_joint"
    type="fixed">
    <origin
      xyz="0.020998022706787 -0.0689999999999992 0.00211967978838579"
      rpy="0 0 0" />
    <parent
      link="R_shoulder_pitch_link" />
    <child
      link="R_shoulder_roll_link" />
    <axis
      xyz="-0.999999560849825 0 -0.00093717669522402" />
  </joint>
  <link
    name="R_arm_yaw_link">
    <inertial>
      <origin
        xyz="0.00112 0.005352 -0.11969"
        rpy="0 0 0" />
      <mass
        value="0.49726" />
      <inertia
        ixx="0.000772"
        ixy="-5E-06"
        ixz="-1.1E-05"
        iyy="0.000897"
        iyz="-3.6E-05"
        izz="0.000313" />
    </inertial>
    <visual>
      <origin
        xyz="0 0 0"
        rpy="0 0 0" />
      <geometry>
        <mesh
          filename="../meshes/R_arm_yaw_link.STL" />
      </geometry>
      <material
        name="">
        <color
          rgba="1 1 1 1" />
      </material>
    </visual>
    <!-- <collision>
      <origin
        xyz="0 0 0"
        rpy="0 0 0" />
      <geometry>
        <mesh
          filename="../meshes/R_arm_yaw_link.STL" />
      </geometry>
    </collision> -->
  </link>
  <joint
    name="R_arm_yaw_joint"
    type="fixed">
    <origin
      xyz="-0.0208978515596245 0.00174167974717687 -0.109005717060395"
      rpy="0 0 0" />
    <parent
      link="R_shoulder_roll_link" />
    <child
      link="R_arm_yaw_link" />
    <axis
      xyz="0.000937057047908586 0.0159787132768956 -0.999871893117365" />
  </joint>
  <link
    name="R_elbow_pitch_link">
    <inertial>
      <origin
        xyz="0.070399 0.0071286 0.00017984"
        rpy="0 0 0" />
      <mass
        value="0.11269" />
      <inertia
        ixx="2.6034E-05"
        ixy="1.1E-05"
        ixz="-3.9445E-07"
        iyy="0.00026216"
        iyz="1.1282E-07"
        izz="0.00025445" />
    </inertial>
    <visual>
      <origin
        xyz="0 0 0"
        rpy="0 0 0" />
      <geometry>
        <mesh
          filename="../meshes/R_elbow_pitch_link.STL" />
      </geometry>
      <material
        name="">
        <color
          rgba="0.89804 0.91765 0.92941 1" />
      </material>
    </visual>
    <!-- <collision>
      <origin
        xyz="0 0 0"
        rpy="0 0 0" />
      <geometry>
        <mesh
          filename="../meshes/R_elbow_pitch_link.STL" />
      </geometry>
    </collision> -->
  </link>
  <joint
    name="R_elbow_pitch_joint"
    type="fixed">
    <origin
      xyz="-0.000566347943474543 -0.0163435382796495 -0.13427888146134"
      rpy="0 0 0" />
    <parent
      link="R_arm_yaw_link" />
    <child
      link="R_elbow_pitch_link" />
    <axis
      xyz="0.0374007344799697 0.999172208581159 0.0160025828979922" />
  </joint>
</robot>
